Traceback (most recent call last):
  File "/Users/yuyashibu/anaconda3/lib/python3.10/site-packages/nbclient/client.py", line 730, in _async_poll_for_reply
    msg = await ensure_async(self.kc.shell_channel.get_msg(timeout=new_timeout))
  File "/Users/yuyashibu/anaconda3/lib/python3.10/site-packages/nbclient/util.py", line 96, in ensure_async
    result = await obj
  File "/Users/yuyashibu/anaconda3/lib/python3.10/site-packages/jupyter_client/channels.py", line 230, in get_msg
    raise Empty
_queue.Empty

During handling of the above exception, another exception occurred:

Traceback (most recent call last):
  File "/Users/yuyashibu/anaconda3/lib/python3.10/site-packages/jupyter_cache/executors/utils.py", line 58, in single_nb_execution
    executenb(
  File "/Users/yuyashibu/anaconda3/lib/python3.10/site-packages/nbclient/client.py", line 1204, in execute
    return NotebookClient(nb=nb, resources=resources, km=km, **kwargs).execute()
  File "/Users/yuyashibu/anaconda3/lib/python3.10/site-packages/nbclient/util.py", line 84, in wrapped
    return just_run(coro(*args, **kwargs))
  File "/Users/yuyashibu/anaconda3/lib/python3.10/site-packages/nbclient/util.py", line 62, in just_run
    return loop.run_until_complete(coro)
  File "/Users/yuyashibu/anaconda3/lib/python3.10/asyncio/base_events.py", line 649, in run_until_complete
    return future.result()
  File "/Users/yuyashibu/anaconda3/lib/python3.10/site-packages/nbclient/client.py", line 663, in async_execute
    await self.async_execute_cell(
  File "/Users/yuyashibu/anaconda3/lib/python3.10/site-packages/nbclient/client.py", line 949, in async_execute_cell
    exec_reply = await self.task_poll_for_reply
  File "/Users/yuyashibu/anaconda3/lib/python3.10/site-packages/nbclient/client.py", line 754, in _async_poll_for_reply
    await self._async_handle_timeout(timeout, cell)
  File "/Users/yuyashibu/anaconda3/lib/python3.10/site-packages/nbclient/client.py", line 801, in _async_handle_timeout
    raise CellTimeoutError.error_from_timeout_and_cell(
nbclient.exceptions.CellTimeoutError: A cell timed out while it was being executed, after 600 seconds.
The message was: Cell execution timed out.
Here is a preview of the cell contents:
-------------------
["user = '010'", '# PLEASE REPLACE THE BELOW PATH IF NECESSARY ', 'path = f"./Geolife Trajectories 1.3/Data/{user}/Trajectory"', '', '# List all the files in the target path']
...
['        df = pd.read_csv(fpath, skiprows=6, usecols=[0,1,3,4,5,6], names= column_name)', "        df = df.assign(record_dt = lambda x: pd.to_datetime(x['date'] + ' ' + x['time']), user = user)", '        df_lst.append(df)', '# Concat all read files into one DataFrame.', 'traj_df = pd.concat(df_lst)']
-------------------

